2022-09-18 20:32:13,142 - uvicorn.error - ERROR - Exception in ASGI application
Traceback (most recent call last):
  File "/Users/ryojikn/opt/miniconda3/envs/tf_macos/lib/python3.9/site-packages/uvicorn/protocols/http/httptools_impl.py", line 372, in run_asgi
    result = await app(self.scope, self.receive, self.send)
  File "/Users/ryojikn/opt/miniconda3/envs/tf_macos/lib/python3.9/site-packages/uvicorn/middleware/proxy_headers.py", line 75, in __call__
    return await self.app(scope, receive, send)
  File "/Users/ryojikn/opt/miniconda3/envs/tf_macos/lib/python3.9/site-packages/uvicorn/middleware/message_logger.py", line 82, in __call__
    raise exc from None
  File "/Users/ryojikn/opt/miniconda3/envs/tf_macos/lib/python3.9/site-packages/uvicorn/middleware/message_logger.py", line 78, in __call__
    await self.app(scope, inner_receive, inner_send)
  File "/Users/ryojikn/opt/miniconda3/envs/tf_macos/lib/python3.9/site-packages/fastapi/applications.py", line 199, in __call__
    await super().__call__(scope, receive, send)
  File "/Users/ryojikn/opt/miniconda3/envs/tf_macos/lib/python3.9/site-packages/starlette/applications.py", line 112, in __call__
    await self.middleware_stack(scope, receive, send)
  File "/Users/ryojikn/opt/miniconda3/envs/tf_macos/lib/python3.9/site-packages/starlette/middleware/errors.py", line 181, in __call__
    raise exc from None
  File "/Users/ryojikn/opt/miniconda3/envs/tf_macos/lib/python3.9/site-packages/starlette/middleware/errors.py", line 159, in __call__
    await self.app(scope, receive, _send)
  File "/Users/ryojikn/opt/miniconda3/envs/tf_macos/lib/python3.9/site-packages/starlette/exceptions.py", line 82, in __call__
    raise exc from None
  File "/Users/ryojikn/opt/miniconda3/envs/tf_macos/lib/python3.9/site-packages/starlette/exceptions.py", line 71, in __call__
    await self.app(scope, receive, sender)
  File "/Users/ryojikn/opt/miniconda3/envs/tf_macos/lib/python3.9/site-packages/starlette/routing.py", line 580, in __call__
    await route.handle(scope, receive, send)
  File "/Users/ryojikn/opt/miniconda3/envs/tf_macos/lib/python3.9/site-packages/starlette/routing.py", line 241, in handle
    await self.app(scope, receive, send)
  File "/Users/ryojikn/opt/miniconda3/envs/tf_macos/lib/python3.9/site-packages/starlette/routing.py", line 52, in app
    response = await func(request)
  File "/Users/ryojikn/opt/miniconda3/envs/tf_macos/lib/python3.9/site-packages/fastapi/routing.py", line 227, in app
    response_data = await serialize_response(
  File "/Users/ryojikn/opt/miniconda3/envs/tf_macos/lib/python3.9/site-packages/fastapi/routing.py", line 113, in serialize_response
    response_content = _prepare_response_content(
  File "/Users/ryojikn/opt/miniconda3/envs/tf_macos/lib/python3.9/site-packages/fastapi/routing.py", line 95, in _prepare_response_content
    return dataclasses.asdict(res)
  File "/Users/ryojikn/opt/miniconda3/envs/tf_macos/lib/python3.9/dataclasses.py", line 1075, in asdict
    return _asdict_inner(obj, dict_factory)
  File "/Users/ryojikn/opt/miniconda3/envs/tf_macos/lib/python3.9/dataclasses.py", line 1082, in _asdict_inner
    value = _asdict_inner(getattr(obj, f.name), dict_factory)
AttributeError: 'DataNodeMetadata' object has no attribute 'plot'
